Workbook
Name Slicer_Attrition: #N/A
Name Slicer_Department: #N/A
Name Slicer_JobRole: #N/A

Sheet WA_Fn-UseC_-HR-Employee-Attriti
A1: Age | B1: Attrition | C1: BusinessTravel | D1: DailyRate | E1: Department | F1: DistanceFromHome | G1: Education | H1: EducationField | I1: EmployeeCount | J1: EmployeeNumber | K1: EnvironmentSatisfaction | L1: Gender | M1: HourlyRate | N1: JobInvolvement | O1: JobLevel | P1: JobRole | Q1: JobSatisfaction | R1: MaritalStatus | S1: MonthlyIncome | T1: MonthlyRate | U1: NumCompaniesWorked | V1: Over18 | W1: OverTime | X1: PercentSalaryHike | Y1: PerformanceRating | Z1: RelationshipSatisfaction | AA1: StandardHours | AB1: StockOptionLevel | AC1: TotalWorkingYears | AD1: TrainingTimesLastYear | AE1: WorkLifeBalance | AF1: YearsAtCompany | AG1: YearsInCurrentRole | AH1: YearsSinceLastPromotion | AI1: YearsWithCurrManager
A2: 41 | B2: Yes | C2: Travel_Rarely | D2: 1102 | E2: Sales | F2: 1 | G2: 2 | H2: Life Sciences | I2: 1 | J2: 1 | K2: 2 | L2: Female | M2: 94 | N2: 3 | O2: 2 | P2: Sales Executive | Q2: 4 | R2: Single | S2: 5993 | T2: 19479 | U2: 8 | V2: Y | W2: Yes | X2: 11 | Y2: 3 | Z2: 1 | AA2: 80 | AB2: 0 | AC2: 8 | AD2: 0 | AE2: 1 | AF2: 6 | AG2: 4 | AH2: 0 | AI2: 5
A3: 49 | B3: No | C3: Travel_Frequently | D3: 279 | E3: Research & Development | F3: 8 | G3: 1 | H3: Life Sciences | I3: 1 | J3: 2 | K3: 3 | L3: Male | M3: 61 | N3: 2 | O3: 2 | P3: Research Scientist | Q3: 2 | R3: Married | S3: 5130 | T3: 24907 | U3: 1 | V3: Y | W3: No | X3: 23 | Y3: 4 | Z3: 4 | AA3: 80 | AB3: 1 | AC3: 10 | AD3: 3 | AE3: 3 | AF3: 10 | AG3: 7 | AH3: 1 | AI3: 7
A4: 37 | B4: Yes | C4: Travel_Rarely | D4: 1373 | E4: Research & Development | F4: 2 | G4: 2 | H4: Other | I4: 1 | J4: 4 | K4: 4 | L4: Male | M4: 92 | N4: 2 | O4: 1 | P4: Laboratory Technician | Q4: 3 | R4: Single | S4: 2090 | T4: 2396 | U4: 6 | V4: Y | W4: Yes | X4: 15 | Y4: 3 | Z4: 2 | AA4: 80 | AB4: 0 | AC4: 7 | AD4: 3 | AE4: 3 | AF4: 0 | AG4: 0 | AH4: 0 | AI4: 0
A5: 33 | B5: No | C5: Travel_Frequently | D5: 1392 | E5: Research & Development | F5: 3 | G5: 4 | H5: Life Sciences | I5: 1 | J5: 5 | K5: 4 | L5: Female | M5: 56 | N5: 3 | O5: 1 | P5: Research Scientist | Q5: 3 | R5: Married | S5: 2909 | T5: 23159 | U5: 1 | V5: Y | W5: Yes | X5: 11 | Y5: 3 | Z5: 3 | AA5: 80 | AB5: 0 | AC5: 8 | AD5: 3 | AE5: 3 | AF5: 8 | AG5: 7 | AH5: 3 | AI5: 0
A6: 27 | B6: No | C6: Travel_Rarely | D6: 591 | E6: Research & Development | F6: 2 | G6: 1 | H6: Medical | I6: 1 | J6: 7 | K6: 1 | L6: Male | M6: 40 | N6: 3 | O6: 1 | P6: Laboratory Technician | Q6: 2 | R6: Married | S6: 3468 | T6: 16632 | U6: 9 | V6: Y | W6: No | X6: 12 | Y6: 3 | Z6: 4 | AA6: 80 | AB6: 1 | AC6: 6 | AD6: 3 | AE6: 3 | AF6: 2 | AG6: 2 | AH6: 2 | AI6: 2
A7: 32 | B7: No | C7: Travel_Frequently | D7: 1005 | E7: Research & Development | F7: 2 | G7: 2 | H7: Life Sciences | I7: 1 | J7: 8 | K7: 4 | L7: Male | M7: 79 | N7: 3 | O7: 1 | P7: Laboratory Technician | Q7: 4 | R7: Single | S7: 3068 | T7: 11864 | U7: 0 | V7: Y | W7: No | X7: 13 | Y7: 3 | Z7: 3 | AA7: 80 | AB7: 0 | AC7: 8 | AD7: 2 | AE7: 2 | AF7: 7 | AG7: 7 | AH7: 3 | AI7: 6
A8: 59 | B8: No | C8: Travel_Rarely | D8: 1324 | E8: Research & Development | F8: 3 | G8: 3 | H8: Medical | I8: 1 | J8: 10 | K8: 3 | L8: Female | M8: 81 | N8: 4 | O8: 1 | P8: Laboratory Technician | Q8: 1 | R8: Married | S8: 2670 | T8: 9964 | U8: 4 | V8: Y | W8: Yes | X8: 20 | Y8: 4 | Z8: 1 | AA8: 80 | AB8: 3 | AC8: 12 | AD8: 3 | AE8: 2 | AF8: 1 | AG8: 0 | AH8: 0 | AI8: 0
A9: 30 | B9: No | C9: Travel_Rarely | D9: 1358 | E9: Research & Development | F9: 24 | G9: 1 | H9: Life Sciences | I9: 1 | J9: 11 | K9: 4 | L9: Male | M9: 67 | N9: 3 | O9: 1 | P9: Laboratory Technician | Q9: 3 | R9: Divorced | S9: 2693 | T9: 13335 | U9: 1 | V9: Y | W9: No | X9: 22 | Y9: 4 | Z9: 2 | AA9: 80 | AB9: 1 | AC9: 1 | AD9: 2 | AE9: 3 | AF9: 1 | AG9: 0 | AH9: 0 | AI9: 0
A10: 38 | B10: No | C10: Travel_Frequently | D10: 216 | E10: Research & Development | F10: 23 | G10: 3 | H10: Life Sciences | I10: 1 | J10: 12 | K10: 4 | L10: Male | M10: 44 | N10: 2 | O10: 3 | P10: Manufacturing Director | Q10: 3 | R10: Single | S10: 9526 | T10: 8787 | U10: 0 | V10: Y | W10: No | X10: 21 | Y10: 4 | Z10: 2 | AA10: 80 | AB10: 0 | AC10: 10 | AD10: 2 | AE10: 3 | AF10: 9 | AG10: 7 | AH10: 1 | AI10: 8
A11: 36 | B11: No | C11: Travel_Rarely | D11: 1299 | E11: Research & Development | F11: 27 | G11: 3 | H11: Medical | I11: 1 | J11: 13 | K11: 3 | L11: Male | M11: 94 | N11: 3 | O11: 2 | P11: Healthcare Representative | Q11: 3 | R11: Married | S11: 5237 | T11: 16577 | U11: 6 | V11: Y | W11: No | X11: 13 | Y11: 3 | Z11: 2 | AA11: 80 | AB11: 2 | AC11: 17 | AD11: 3 | AE11: 2 | AF11: 7 | AG11: 7 | AH11: 7 | AI11: 7
A12: 35 | B12: No | C12: Travel_Rarely | D12: 809 | E12: Research & Development | F12: 16 | G12: 3 | H12: Medical | I12: 1 | J12: 14 | K12: 1 | L12: Male | M12: 84 | N12: 4 | O12: 1 | P12: Laboratory Technician | Q12: 2 | R12: Married | S12: 2426 | T12: 16479 | U12: 0 | V12: Y | W12: No | X12: 13 | Y12: 3 | Z12: 3 | AA12: 80 | AB12: 1 | AC12: 6 | AD12: 5 | AE12: 3 | AF12: 5 | AG12: 4 | AH12: 0 | AI12: 3
A13: 29 | B13: No | C13: Travel_Rarely | D13: 153 | E13: Research & Development | F13: 15 | G13: 2 | H13: Life Sciences | I13: 1 | J13: 15 | K13: 4 | L13: Female | M13: 49 | N13: 2 | O13: 2 | P13: Laboratory Technician | Q13: 3 | R13: Single | S13: 4193 | T13: 12682 | U13: 0 | V13: Y | W13: Yes | X13: 12 | Y13: 3 | Z13: 4 | AA13: 80 | AB13: 0 | AC13: 10 | AD13: 3 | AE13: 3 | AF13: 9 | AG13: 5 | AH13: 0 | AI13: 8
... A1471: 34 | B1471: No | C1471: Travel_Rarely | D1471: 628 | E1471: Research & Development | F1471: 8 | G1471: 3 | H1471: Medical | I1471: 1 | J1471: 2068 | K1471: 2 | L1471: Male | M1471: 82 | N1471: 4 | O1471: 2 | P1471: Laboratory Technician | Q1471: 3 | R1471: Married | S1471: 4404 | T1471: 10228 | U1471: 2 | V1471: Y | W1471: No | X1471: 12 | Y1471: 3 | Z1471: 1 | AA1471: 80 | AB1471: 0 | AC1471: 6 | AD1471: 3 | AE1471: 4 | AF1471: 4 | AG1471: 3 | AH1471: 1 | AI1471: 2

Sheet WotkSheet
A1: العمر | C1: الاستقاله | D1: سفر العمل | E1: الاجراليومي | F1: القسم | G1: المسافه من البيت | H1: التعليم | I1: مجال التعليم | J1: عدد الموظفين | K1: رقم الموظف | L1: رضا بيئه العمل | M1: الجنس | N1: الاجربالساعه | O1: الانخراط في العمل | P1: المستوي الوظيفي | Q1: الدور الوظيفي | R1: رضا الوظيفه | S1: الحاله الاجتماعيه | T1: الدخل الشهري | V1: الاجر الشهري | W1: عدد الشركات | X1: اكتر من 18 | Y1: عمل اضافي | Z1: نسبه زياده الراتب | AA1: تقييم الاداء | AB1: رضا العلاقات | AC1: ساعات العمل القياسيه | AD1: مستوي خيارات الاسهم | AE1: اجمالي سنوات العمل | AF1: عدد مرات التدريب العام الماضي | AG1: التوازن بين العمل و الحياه | AI1: سنوات العمل في الشركه | AJ1: سنوات العمل في المنصب الحالي | AK1: سنوات منذ اخر ترقيه | AL1: سنوات العمل مع المدير الحالي
A2: Age | B2: Age Segments | C2: Attrition | D2: BusinessTravel | E2: DailyRate | F2: Department | G2: DistanceFromHome | H2: Education | I2: EducationField | J2: EmployeeCount | K2: EmployeeNumber | L2: EnvironmentSatisfaction | M2: Gender | N2: HourlyRate | O2: JobInvolvement | P2: JobLevel | Q2: JobRole | R2: JobSatisfaction | S2: MaritalStatus | T2: MonthlyIncome | U2: Salary Group | V2: MonthlyRate | W2: NumCompaniesWorked | X2: Over18 | Y2: OverTime | Z2: PercentSalaryHike | AA2: PerformanceRating | AB2: RelationshipSatisfaction | AC2: StandardHours | AD2: StockOptionLevel | AE2: TotalWorkingYears | AF2: TrainingTimesLastYear | AG2: WorkLifeBalance | AH2: Years Group | AI2: YearsAtCompany | AJ2: YearsInCurrentRole | AK2: YearsSinceLastPromotion | AL2: YearsWithCurrManager
A3: 41 | B3: =IF(A3<=30,"Early Career (18-30)", IF(A3<=45,"Mid Career (31-45)", "Late Career (46+)")) -> Mid Career (31-45) | C3: Yes | D3: Travel_Rarely | E3: 1102 | F3: Sales | G3: 1 | H3: 2 | I3: Life Sciences | J3: 1 | K3: 1 | L3: 2 | M3: Female | N3: 94 | O3: 3 | P3: 2 | Q3: Sales Executive | R3: 4 | S3: Single | T3: 5993 | U3: =IF(T3<3000,"Low", IF(T3<7000,"Medium", "High")) -> Medium | V3: 19479 | W3: 8 | X3: Y | Y3: Yes | Z3: 11 | AA3: 3 | AB3: 1 | AC3: 80 | AD3: 0 | AE3: 8 | AF3: 0 | AG3: 1 | AH3: =IF(AI3<=2,"0-2 Years", IF(AI3<=5,"3-5 Years", "6+ Years")) -> 6+ Years | AI3: 6 | AJ3: 4 | AK3: 0 | AL3: 5
A4: 49 | B4: =IF(A4<=30,"Early Career (18-30)", IF(A4<=45,"Mid Career (31-45)", "Late Career (46+)")) -> Late Career (46+) | C4: No | D4: Travel_Frequently | E4: 279 | F4: Research & Development | G4: 8 | H4: 1 | I4: Life Sciences | J4: 1 | K4: 2 | L4: 3 | M4: Male | N4: 61 | O4: 2 | P4: 2 | Q4: Research Scientist | R4: 2 | S4: Married | T4: 5130 | U4: =IF(T4<3000,"Low", IF(T4<7000,"Medium", "High")) -> Medium | V4: 24907 | W4: 1 | X4: Y | Y4: No | Z4: 23 | AA4: 4 | AB4: 4 | AC4: 80 | AD4: 1 | AE4: 10 | AF4: 3 | AG4: 3 | AH4: =IF(AI4<=2,"0-2 Years", IF(AI4<=5,"3-5 Years", "6+ Years")) -> 6+ Years | AI4: 10 | AJ4: 7 | AK4: 1 | AL4: 7
A5: 37 | B5: =IF(A5<=30,"Early Career (18-30)", IF(A5<=45,"Mid Career (31-45)", "Late Career (46+)")) -> Mid Career (31-45) | C5: Yes | D5: Travel_Rarely | E5: 1373 | F5: Research & Development | G5: 2 | H5: 2 | I5: Other | J5: 1 | K5: 4 | L5: 4 | M5: Male | N5: 92 | O5: 2 | P5: 1 | Q5: Laboratory Technician | R5: 3 | S5: Single | T5: 2090 | U5: =IF(T5<3000,"Low", IF(T5<7000,"Medium", "High")) -> Low | V5: 2396 | W5: 6 | X5: Y | Y5: Yes | Z5: 15 | AA5: 3 | AB5: 2 | AC5: 80 | AD5: 0 | AE5: 7 | AF5: 3 | AG5: 3 | AH5: =IF(AI5<=2,"0-2 Years", IF(AI5<=5,"3-5 Years", "6+ Years")) -> 0-2 Years | AI5: 0 | AJ5: 0 | AK5: 0 | AL5: 0
A6: 33 | B6: =IF(A6<=30,"Early Career (18-30)", IF(A6<=45,"Mid Career (31-45)", "Late Career (46+)")) -> Mid Career (31-45) | C6: No | D6: Travel_Frequently | E6: 1392 | F6: Research & Development | G6: 3 | H6: 4 | I6: Life Sciences | J6: 1 | K6: 5 | L6: 4 | M6: Female | N6: 56 | O6: 3 | P6: 1 | Q6: Research Scientist | R6: 3 | S6: Married | T6: 2909 | U6: =IF(T6<3000,"Low", IF(T6<7000,"Medium", "High")) -> Low | V6: 23159 | W6: 1 | X6: Y | Y6: Yes | Z6: 11 | AA6: 3 | AB6: 3 | AC6: 80 | AD6: 0 | AE6: 8 | AF6: 3 | AG6: 3 | AH6: =IF(AI6<=2,"0-2 Years", IF(AI6<=5,"3-5 Years", "6+ Years")) -> 6+ Years | AI6: 8 | AJ6: 7 | AK6: 3 | AL6: 0
A7: 27 | B7: =IF(A7<=30,"Early Career (18-30)", IF(A7<=45,"Mid Career (31-45)", "Late Career (46+)")) -> Early Career (18-30) | C7: No | D7: Travel_Rarely | E7: 591 | F7: Research & Development | G7: 2 | H7: 1 | I7: Medical | J7: 1 | K7: 7 | L7: 1 | M7: Male | N7: 40 | O7: 3 | P7: 1 | Q7: Laboratory Technician | R7: 2 | S7: Married | T7: 3468 | U7: =IF(T7<3000,"Low", IF(T7<7000,"Medium", "High")) -> Medium | V7: 16632 | W7: 9 | X7: Y | Y7: No | Z7: 12 | AA7: 3 | AB7: 4 | AC7: 80 | AD7: 1 | AE7: 6 | AF7: 3 | AG7: 3 | AH7: =IF(AI7<=2,"0-2 Years", IF(AI7<=5,"3-5 Years", "6+ Years")) -> 0-2 Years | AI7: 2 | AJ7: 2 | AK7: 2 | AL7: 2
A8: 32 | B8: =IF(A8<=30,"Early Career (18-30)", IF(A8<=45,"Mid Career (31-45)", "Late Career (46+)")) -> Mid Career (31-45) | C8: No | D8: Travel_Frequently | E8: 1005 | F8: Research & Development | G8: 2 | H8: 2 | I8: Life Sciences | J8: 1 | K8: 8 | L8: 4 | M8: Male | N8: 79 | O8: 3 | P8: 1 | Q8: Laboratory Technician | R8: 4 | S8: Single | T8: 3068 | U8: =IF(T8<3000,"Low", IF(T8<7000,"Medium", "High")) -> Medium | V8: 11864 | W8: 0 | X8: Y | Y8: No | Z8: 13 | AA8: 3 | AB8: 3 | AC8: 80 | AD8: 0 | AE8: 8 | AF8: 2 | AG8: 2 | AH8: =IF(AI8<=2,"0-2 Years", IF(AI8<=5,"3-5 Years", "6+ Years")) -> 6+ Years | AI8: 7 | AJ8: 7 | AK8: 3 | AL8: 6
A9: 59 | B9: =IF(A9<=30,"Early Career (18-30)", IF(A9<=45,"Mid Career (31-45)", "Late Career (46+)")) -> Late Career (46+) | C9: No | D9: Travel_Rarely | E9: 1324 | F9: Research & Development | G9: 3 | H9: 3 | I9: Medical | J9: 1 | K9: 10 | L9: 3 | M9: Female | N9: 81 | O9: 4 | P9: 1 | Q9: Laboratory Technician | R9: 1 | S9: Married | T9: 2670 | U9: =IF(T9<3000,"Low", IF(T9<7000,"Medium", "High")) -> Low | V9: 9964 | W9: 4 | X9: Y | Y9: Yes | Z9: 20 | AA9: 4 | AB9: 1 | AC9: 80 | AD9: 3 | AE9: 12 | AF9: 3 | AG9: 2 | AH9: =IF(AI9<=2,"0-2 Years", IF(AI9<=5,"3-5 Years", "6+ Years")) -> 0-2 Years | AI9: 1 | AJ9: 0 | AK9: 0 | AL9: 0
A10: 30 | B10: =IF(A10<=30,"Early Career (18-30)", IF(A10<=45,"Mid Career (31-45)", "Late Career (46+)")) -> Early Career (18-30) | C10: No | D10: Travel_Rarely | E10: 1358 | F10: Research & Development | G10: 24 | H10: 1 | I10: Life Sciences | J10: 1 | K10: 11 | L10: 4 | M10: Male | N10: 67 | O10: 3 | P10: 1 | Q10: Laboratory Technician | R10: 3 | S10: Divorced | T10: 2693 | U10: =IF(T10<3000,"Low", IF(T10<7000,"Medium", "High")) -> Low | V10: 13335 | W10: 1 | X10: Y | Y10: No | Z10: 22 | AA10: 4 | AB10: 2 | AC10: 80 | AD10: 1 | AE10: 1 | AF10: 2 | AG10: 3 | AH10: =IF(AI10<=2,"0-2 Years", IF(AI10<=5,"3-5 Years", "6+ Years")) -> 0-2 Years | AI10: 1 | AJ10: 0 | AK10: 0 | AL10: 0
A11: 38 | B11: =IF(A11<=30,"Early Career (18-30)", IF(A11<=45,"Mid Career (31-45)", "Late Career (46+)")) -> Mid Career (31-45) | C11: No | D11: Travel_Frequently | E11: 216 | F11: Research & Development | G11: 23 | H11: 3 | I11: Life Sciences | J11: 1 | K11: 12 | L11: 4 | M11: Male | N11: 44 | O11: 2 | P11: 3 | Q11: Manufacturing Director | R11: 3 | S11: Single | T11: 9526 | U11: =IF(T11<3000,"Low", IF(T11<7000,"Medium", "High")) -> High | V11: 8787 | W11: 0 | X11: Y | Y11: No | Z11: 21 | AA11: 4 | AB11: 2 | AC11: 80 | AD11: 0 | AE11: 10 | AF11: 2 | AG11: 3 | AH11: =IF(AI11<=2,"0-2 Years", IF(AI11<=5,"3-5 Years", "6+ Years")) -> 6+ Years | AI11: 9 | AJ11: 7 | AK11: 1 | AL11: 8
A12: 36 | B12: =IF(A12<=30,"Early Career (18-30)", IF(A12<=45,"Mid Career (31-45)", "Late Career (46+)")) -> Mid Career (31-45) | C12: No | D12: Travel_Rarely | E12: 1299 | F12: Research & Development | G12: 27 | H12: 3 | I12: Medical | J12: 1 | K12: 13 | L12: 3 | M12: Male | N12: 94 | O12: 3 | P12: 2 | Q12: Healthcare Representative | R12: 3 | S12: Married | T12: 5237 | U12: =IF(T12<3000,"Low", IF(T12<7000,"Medium", "High")) -> Medium | V12: 16577 | W12: 6 | X12: Y | Y12: No | Z12: 13 | AA12: 3 | AB12: 2 | AC12: 80 | AD12: 2 | AE12: 17 | AF12: 3 | AG12: 2 | AH12: =IF(AI12<=2,"0-2 Years", IF(AI12<=5,"3-5 Years", "6+ Years")) -> 6+ Years | AI12: 7 | AJ12: 7 | AK12: 7 | AL12: 7
A13: 35 | B13: =IF(A13<=30,"Early Career (18-30)", IF(A13<=45,"Mid Career (31-45)", "Late Career (46+)")) -> Mid Career (31-45) | C13: No | D13: Travel_Rarely | E13: 809 | F13: Research & Development | G13: 16 | H13: 3 | I13: Medical | J13: 1 | K13: 14 | L13: 1 | M13: Male | N13: 84 | O13: 4 | P13: 1 | Q13: Laboratory Technician | R13: 2 | S13: Married | T13: 2426 | U13: =IF(T13<3000,"Low", IF(T13<7000,"Medium", "High")) -> Low | V13: 16479 | W13: 0 | X13: Y | Y13: No | Z13: 13 | AA13: 3 | AB13: 3 | AC13: 80 | AD13: 1 | AE13: 6 | AF13: 5 | AG13: 3 | AH13: =IF(AI13<=2,"0-2 Years", IF(AI13<=5,"3-5 Years", "6+ Years")) -> 3-5 Years | AI13: 5 | AJ13: 4 | AK13: 0 | AL13: 3
A14: 29 | B14: =IF(A14<=30,"Early Career (18-30)", IF(A14<=45,"Mid Career (31-45)", "Late Career (46+)")) -> Early Career (18-30) | C14: No | D14: Travel_Rarely | E14: 153 | F14: Research & Development | G14: 15 | H14: 2 | I14: Life Sciences | J14: 1 | K14: 15 | L14: 4 | M14: Female | N14: 49 | O14: 2 | P14: 2 | Q14: Laboratory Technician | R14: 3 | S14: Single | T14: 4193 | U14: =IF(T14<3000,"Low", IF(T14<7000,"Medium", "High")) -> Medium | V14: 12682 | W14: 0 | X14: Y | Y14: Yes | Z14: 12 | AA14: 3 | AB14: 4 | AC14: 80 | AD14: 0 | AE14: 10 | AF14: 3 | AG14: 3 | AH14: =IF(AI14<=2,"0-2 Years", IF(AI14<=5,"3-5 Years", "6+ Years")) -> 6+ Years | AI14: 9 | AJ14: 5 | AK14: 0 | AL14: 8
... A1472: 34 | B1472: =IF(A1472<=30,"Early Career (18-30)", IF(A1472<=45,"Mid Career (31-45)", "Late Career (46+)")) -> Mid Career (31-45) | C1472: No | D1472: Travel_Rarely | E1472: 628 | F1472: Research & Development | G1472: 8 | H1472: 3 | I1472: Medical | J1472: 1 | K1472: 2068 | L1472: 2 | M1472: Male | N1472: 82 | O1472: 4 | P1472: 2 | Q1472: Laboratory Technician | R1472: 3 | S1472: Married | T1472: 4404 | U1472: =IF(T1472<3000,"Low", IF(T1472<7000,"Medium", "High")) -> Medium | V1472: 10228 | W1472: 2 | X1472: Y | Y1472: No | Z1472: 12 | AA1472: 3 | AB1472: 1 | AC1472: 80 | AD1472: 0 | AE1472: 6 | AF1472: 3 | AG1472: 4 | AH1472: =IF(AI1472<=2,"0-2 Years", IF(AI1472<=5,"3-5 Years", "6+ Years")) -> 3-5 Years | AI1472: 4 | AJ1472: 3 | AK1472: 1 | AL1472: 2
A1473: =SUBTOTAL(105,EmployeeData[Age]) -> 18 | J1473: =SUBTOTAL(109,EmployeeData[EmployeeCount]) -> 1470 | K1473: =SUBTOTAL(103,EmployeeData[EmployeeNumber]) -> 1470
A1475: Avg | C1475: No | M1475: Male | S1475: Married | Y1475: Yes
A1476: 37 | C1476: =COUNTIF(C2:C1472,"No") -> 1233 | M1476: =COUNTIF(M2:M1472,"Male") -> 882 | S1476: =COUNTIF(S2:S1472,"Married") -> 673 | Y1476: =COUNTIF(Y2:Y1472,"Yes") -> 416
A1477: Max | C1477: Yes | M1477: Female | S1477: Single | Y1477: No
A1478: 60 | C1478: =COUNTIF(C3:C1472,"Yes") -> 237 | M1478: =COUNTIF(M2:M1472,"FeMale") -> 588 | S1478: =COUNTIF(S2:S1472,"Single") -> 470 | Y1478: =COUNTIF(Y2:Y1472,"No") -> 1054
A1479: Min | S1479: Divorced
A1480: 18 | S1480: =COUNTIF(S2:S1472,"Divorced") -> 327

Sheet Dashboard
A1: This is a view-only dashboard. Use slicers to interact
E9: Total Employee | G9: Attrition % | I9: Avg Age | K9: Avg of Monthly Income | O9: Avg Year At Company | S9: Gender
E11: ='Pivot Table'!A10 -> 1470 | G11: ='Pivot Table'!E10 -> 0.16122449 | I11: ='Pivot Table'!B10 -> 36.92381 | K11: ='Pivot Table'!C10 -> 6502.9313 | O11: ='Pivot Table'!D10 -> 7.0081633 | S11: ='Pivot Table'!I33 -> 0.10204082 | U11: ='Pivot Table'!I32 -> 0.059183673
A36: Improving employee experience in early stages and reducing overtime can help lower attrition rates.

Sheet Dashboard2
A1: This is a view-only dashboard. Use slicers to interact
E9: Total Employee | G9: Attrition % | I9: Avg Age | K9: Avg of Monthly Income | O9: Avg Year At Company | S9: Gender
E11: ='Pivot Table'!A10 -> 1470 | G11: ='Pivot Table'!E10 -> 0.16122449 | I11: ='Pivot Table'!B10 -> 36.92381 | K11: ='Pivot Table'!C10 -> 6502.9313 | O11: ='Pivot Table'!D10 -> 7.0081633 | S11: ='Pivot Table'!I33 -> 0.10204082 | U11: ='Pivot Table'!I32 -> 0.059183673

Sheet Pivot Table
A5: KPI
A9: Count of EmployeeNumber | B9: Average of Age | C9: Average of MonthlyIncome | D9: Average of YearsAtCompany | E9: Attrition %
A10: 1470 | B10: 36.92381 | C10: 6502.9313 | D10: 7.0081633 | E10: =B19/B20 -> 0.16122449
A17: Row Labels | B17: Sum of EmployeeCount
A18: No | B18: 1233
A19: Yes | B19: 237
A20: Grand Total | B20: 1470
A30: Row Labels | B30: Count of Attrition | G30: Sum of EmployeeCount | H30: Column Labels
A31: Human Resources | B31: 63 | G31: Row Labels | H31: No | I31: Yes | J31: Grand Total
A32: Research & Development | B32: 961 | G32: Female | H32: 0.34081633 | I32: 0.059183673 | J32: 0.4
A33: Sales | B33: 446 | G33: Male | H33: 0.49795918 | I33: 0.10204082 | J33: 0.6
A34: Grand Total | B34: 1470 | G34: Grand Total | H34: 0.83877551 | I34: 0.16122449 | J34: 1
A53: Sum of PercentSalaryHike | B53: Column Labels | G53: Row Labels | H53: Sum of PercentSalaryHike
A54: Row Labels | B54: No | C54: Yes | D54: Grand Total | G54: No | H54: 0.71759549
A55: No | B55: 0.64478039 | C55: 0.0728151 | D55: 0.71759549 | G55: Yes | H55: 0.28240451
A56: Yes | B56: 0.1951874 | C56: 0.087217103 | D56: 0.28240451 | G56: Grand Total | H56: 1
A57: Grand Total | B57: 0.8399678 | C57: 0.1600322 | D57: 1
G73: Sum of EmployeeCount | H73: Column Labels
G74: Row Labels | H74: No | I74: Yes | J74: Grand Total
G75: Divorced | H75: 294 | I75: 33 | J75: 327
G76: Married | H76: 589 | I76: 84 | J76: 673
G77: Single | H77: 350 | I77: 120 | J77: 470
G78: Grand Total | H78: 1233 | I78: 237 | J78: 1470
A81: Row Labels | B81: Count of Attrition | C81: Average of DistanceFromHome
A82: Human Resources | B82: 63 | C82: 8.6984127
A83: Research & Development | B83: 961 | C83: 9.144641
A84: Sales | B84: 446 | C84: 9.3654709
A85: Grand Total | B85: 1470 | C85: 9.192517
A99: Sum of EmployeeCount | B99: Column Labels | G99: Row Labels | H99: Count of Attrition
A100: Row Labels | B100: No | C100: Yes | D100: Grand Total | G100: Healthcare Representative | H100: 131
A101: 0-2 Years | B101: 240 | C101: 102 | D101: 342 | G101: Human Resources | H101: 52
A102: 3-5 Years | B102: 374 | C102: 60 | D102: 434 | G102: Laboratory Technician | H102: 259
A103: 6+ Years | B103: 619 | C103: 75 | D103: 694 | G103: Manager | H103: 102
A104: Grand Total | B104: 1233 | C104: 237 | D104: 1470 | G104: Manufacturing Director | H104: 145
G105: Research Director | H105: 80
G106: Research Scientist | H106: 292
G107: Sales Executive | H107: 326
G108: Sales Representative | H108: 83
G109: Grand Total | H109: 1470
A147: Count of MaritalStatus | B147: Column Labels | G147: Count of Over18 | H147: Column Labels
...
